Workbook

Sheet Recommendations
A1: Symbol | B1: C.M.P | C1: Difference (%) | D1: Price Position (%) | E1: Composite Score | F1: Target Buy Price | G1: Quantity to Buy | H1: Investment Amount | K1: NIFTY VIX > | L1: =IFERROR(__xludf.DUMMYFUNCTION("IMPORTXML(""https://www.google.com/finance/quote/INDIA_VIX:INDEXNSE?hl=en"", ""//div[@class='YMlKec fxKbKc']"") "),14.54) -> 14.54 | N1: To Invest 2x > | O1: 10000
A2: KPITTECH | B2: 772.9 | C2: 0.0783 | D2: 0.5388 | E2: 0.4946 | F2: 766.4 | G2: 1 | H2: 766.4
A3: IRCON | B3: 147.31 | C3: 0.0443 | D3: 0.6532 | E3: 0.4744 | F3: 146.07 | G3: 1 | H3: 146.07
A4: TEXRAIL | B4: 107.5 | C4: 0.0138 | D4: 0.5688 | E4: 0.4453 | F4: 106.6 | G4: 1 | H4: 106.6
A5: OLECTRA | B5: 1016.1 | C5: 0.0648 | D5: 0.5928 | E5: 0.4431 | F5: 1007.56 | G5: 1 | H5: 1007.56
A6: NTPCGREEN | B6: 89.71 | C6: 0.0072 | D6: 0.7626 | E6: 0.442 | F6: 88.96 | G6: 7 | H6: 622.69
A7: INDOWIND | B7: 9.71 | C7: 0.0079 | D7: 0.4099 | E7: 0.4044 | F7: 9.63 | G7: 64 | H7: 616.22
A8: Total Investment | H8: 3265.54

Sheet Portfolio
A1: Scrip Name | B1: Scrip Code | C1: Symbol | D1: ISIN | E1: Type | F1: Qty | G1: C.M.P | H1: Avg Buy Price | I1: Total Invested | J1: Total current Value | K1: P&L | L1: P&L (%) | M1: Target buy | N1: New Average | O1: Per share Impact | P1: New P&L | Q1: New P&L (%) | R1: Buy/Not Buy | S1: Difference | T1: PE | U1: MCAP | V1: EPS | W1: High52 | X1: AVG Buy to High52 | Y1: Low52 | Z1: AVG Buy to Low52 | AA1: Daily AVG Volume Traded | AB1: Today's Volume | AC1: Segment | AD1: Moving/Non Moving
A2: ADANI GREEN ENERGY LTD | B2: 541450 | C2: ADANIGREEN | D2: INE364U01010 | E2: Equity | F2: 1 | G2: =IFERROR(__xludf.DUMMYFUNCTION("GOOGLEFINANCE(C2)"),961.4) -> 961.4 | H2: 1640 | I2: =H2*F2 -> 1640 | J2: =G2*F2 -> 961.4 | K2: =J2-I2 -> -678.6 | L2: =K2/I2 -> -0.41378049 | M2: 1 | N2: =(I2 + (M2 * G2)) / (F2 + M2) -> 1300.7 | O2: =G2-N2 -> -339.3 | P2: =O2*F2+M2 -> -338.3 | Q2: =(P2 / (N2 * (F2 + M2))) -> -0.13004536 | R2: =IF(Q2 > L2, "Yes", "No") -> Yes | S2: =Q2-L2 -> 0.28373513 | T2: =IFERROR(__xludf.DUMMYFUNCTION("GOOGLEFINANCE(C2,""pe"")"),111.62) -> 111.62 | U2: =IFERROR(__xludf.DUMMYFUNCTION("GOOGLEFINANCE(C2,""marketcap"")"),1.583594085214E12) -> 1583594085214 | V2: =IFERROR(__xludf.DUMMYFUNCTION("GOOGLEFINANCE(C2,""eps"")"),8.61) -> 8.61 | W2: =IFERROR(__xludf.DUMMYFUNCTION("GOOGLEFINANCE(C2,""high52"")"),1177.55) -> 1177.55 | X2: =H2/W2 -> 1.3927222 | Y2: =IFERROR(__xludf.DUMMYFUNCTION("GOOGLEFINANCE(C2,""low52"")"),758.0) -> 758 | Z2: =H2/Y2 -> 2.1635884 | AA2: =IFERROR(__xludf.DUMMYFUNCTION("GOOGLEFINANCE(C2,""volumeavg"")"),3656090.0) -> 3656090 | AB2: =IFERROR(__xludf.DUMMYFUNCTION("GOOGLEFINANCE(C2,""volume"")"),580689.0) -> 580689 | AC2: Green Energy | AD2: Non Moving
A3: ADANI POWER | B3: 533096 | C3: ADANIPOWER | D3: INE814H01011 | E3: Equity | F3: 10 | G3: =IFERROR(__xludf.DUMMYFUNCTION("GOOGLEFINANCE(C3)"),142.75) -> 142.75 | H3: 119.1 | I3: =H3*F3 -> 1191 | J3: =G3*F3 -> 1427.5 | K3: =J3-I3 -> 236.5 | L3: =K3/I3 -> 0.19857263 | M3: 1 | N3: =(I3 + (M3 * G3)) / (F3 + M3) -> 121.25 | O3: =G3-N3 -> 21.5 | P3: =O3*F3+M3 -> 216 | Q3: =P3/(I3+(G3*M3)) -> 0.16194939 | R3: =IF(Q3 > L3, "Yes", "No") -> No | S3: =Q3-L3 -> -0.036623237 | T3: =IFERROR(__xludf.DUMMYFUNCTION("GOOGLEFINANCE(C3,""pe"")"),23.42) -> 23.42 | U3: =IFERROR(__xludf.DUMMYFUNCTION("GOOGLEFINANCE(C3,""marketcap"")"),2.752503721306E12) -> 2752503721306 | V3: =IFERROR(__xludf.DUMMYFUNCTION("GOOGLEFINANCE(C3,""eps"")"),6.09) -> 6.09 | W3: =IFERROR(__xludf.DUMMYFUNCTION("GOOGLEFINANCE(C3,""high52"")"),182.7) -> 182.7 | X3: =H3/W3 -> 0.65188834 | Y3: =IFERROR(__xludf.DUMMYFUNCTION("GOOGLEFINANCE(C3,""low52"")"),92.4) -> 92.4 | Z3: =H3/Y3 -> 1.288961 | AA3: =IFERROR(__xludf.DUMMYFUNCTION("GOOGLEFINANCE(C3,""volumeavg"")"),1.8709376E7) -> 18709376 | AB3: =IFERROR(__xludf.DUMMYFUNCTION("GOOGLEFINANCE(C3,""volume"")"),4242013.0) -> 4242013 | AC3: Green Energy | AD3: Non Moving
A4: AEROFLEX INDUSTRIES LTD | B4: 543972 | C4: AEROFLEX | D4: INE024001021 | E4: Equity | F4: 9 | G4: =IFERROR(__xludf.DUMMYFUNCTION("GOOGLEFINANCE(C4)"),215.3) -> 215.3 | H4: 134.33 | I4: =H4*F4 -> 1208.97 | J4: =G4*F4 -> 1937.7 | K4: =J4-I4 -> 728.73 | L4: =K4/I4 -> 0.6027693 | M4: 1 | N4: =(I4 + (M4 * G4)) / (F4 + M4) -> 142.427 | O4: =G4-N4 -> 72.873 | P4: =O4*F4+M4 -> 656.857 | Q4: =P4/(I4+(G4*M4)) -> 0.46118854 | R4: =IF(Q4 > L4, "Yes", "No") -> No | S4: =Q4-L4 -> -0.14158076 | T4: =IFERROR(__xludf.DUMMYFUNCTION("GOOGLEFINANCE(C4,""pe"")"),56.68) -> 56.68 | U4: =IFERROR(__xludf.DUMMYFUNCTION("GOOGLEFINANCE(C4,""marketcap"")"),2.8494769873E10) -> 28494769873 | V4: =IFERROR(__xludf.DUMMYFUNCTION("GOOGLEFINANCE(C4,""eps"")"),3.8) -> 3.8 | W4: =IFERROR(__xludf.DUMMYFUNCTION("GOOGLEFINANCE(C4,""high52"")"),233.99) -> 233.99 | X4: =H4/W4 -> 0.57408436 | Y4: =IFERROR(__xludf.DUMMYFUNCTION("GOOGLEFINANCE(C4,""low52"")"),148.01) -> 148.01 | Z4: =H4/Y4 -> 0.90757381 | AA4: =IFERROR(__xludf.DUMMYFUNCTION("GOOGLEFINANCE(C4,""volumeavg"")"),2931461.0) -> 2931461 | AB4: =IFERROR(__xludf.DUMMYFUNCTION("GOOGLEFINANCE(C4,""volume"")"),492296.0) -> 492296 | AC4: Defence | AD4: Moving
A5: ASHOK LEYLND | B5: 500477 | C5: ASHOKLEY | D5: INE208A01029 | E5: Equity | F5: 122 | G5: =IFERROR(__xludf.DUMMYFUNCTION("GOOGLEFINANCE(C5)"),209.78) -> 209.78 | H5: 67.04 | I5: =H5*F5 -> 8178.88 | J5: =G5*F5 -> 25593.16 | K5: =J5-I5 -> 17414.28 | L5: =K5/I5 -> 2.1291766 | M5: 1 | N5: =(I5 + (M5 * G5)) / (F5 + M5) -> 68.200488 | O5: =G5-N5 -> 141.57951 | P5: =O5*F5+M5 -> 17273.7 | Q5: =P5/(I5+(G5*M5)) -> 2.0591728 | R5: =IF(Q5 > L5, "Yes", "No") -> No | S5: =Q5-L5 -> -0.070003812 | T5: =IFERROR(__xludf.DUMMYFUNCTION("GOOGLEFINANCE(C5,""pe"")"),37.28) -> 37.28 | U5: =IFERROR(__xludf.DUMMYFUNCTION("GOOGLEFINANCE(C5,""marketcap"")"),1.232628717451E12) -> 1232628717451 | V5: =IFERROR(__xludf.DUMMYFUNCTION("GOOGLEFINANCE(C5,""eps"")"),5.63) -> 5.63 | W5: =IFERROR(__xludf.DUMMYFUNCTION("GOOGLEFINANCE(C5,""high52"")"),215.42) -> 215.42 | X5: =H5/W5 -> 0.31120602 | Y5: =IFERROR(__xludf.DUMMYFUNCTION("GOOGLEFINANCE(C5,""low52"")"),95.93) -> 95.93 | Z5: =H5/Y5 -> 0.69884291 | AA5: =IFERROR(__xludf.DUMMYFUNCTION("GOOGLEFINANCE(C5,""volumeavg"")"),1.6145546E7) -> 16145546 | AB5: =IFERROR(__xludf.DUMMYFUNCTION("GOOGLEFINANCE(C5,""volume"")"),6583081.0) -> 6583081 | AC5: EV | AD5: Moving
A6: ASTRA MICRO | B6: 532493 | C6: ASTRAMICRO | D6: INE386C01029 | E6: Equity | F6: 8 | G6: =IFERROR(__xludf.DUMMYFUNCTION("GOOGLEFINANCE(C6)"),917.5) -> 917.5 | H6: 729.25 | I6: =H6*F6 -> 5834 | J6: =G6*F6 -> 7340 | K6: =J6-I6 -> 1506 | L6: =K6/I6 -> 0.25814193 | M6: 1 | N6: =(I6 + (M6 * G6)) / (F6 + M6) -> 750.16667 | O6: =G6-N6 -> 167.33333 | P6: =O6*F6+M6 -> 1339.6667 | Q6: =P6/(I6+(G6*M6)) -> 0.19842504 | R6: =IF(Q6 > L6, "Yes", "No") -> No | S6: =Q6-L6 -> -0.059716885 | T6: =IFERROR(__xludf.DUMMYFUNCTION("GOOGLEFINANCE(C6,""pe"")"),54.34) -> 54.34 | U6: =IFERROR(__xludf.DUMMYFUNCTION("GOOGLEFINANCE(C6,""marketcap"")"),8.7036091825E10) -> 87036091825 | V6: =IFERROR(__xludf.DUMMYFUNCTION("GOOGLEFINANCE(C6,""eps"")"),16.88) -> 16.88 | W6: =IFERROR(__xludf.DUMMYFUNCTION("GOOGLEFINANCE(C6,""high52"")"),1195.9) -> 1195.9 | X6: =H6/W6 -> 0.60979179 | Y6: =IFERROR(__xludf.DUMMYFUNCTION("GOOGLEFINANCE(C6,""low52"")"),584.2) -> 584.2 | Z6: =H6/Y6 -> 1.2482883 | AA6: =IFERROR(__xludf.DUMMYFUNCTION("GOOGLEFINANCE(C6,""volumeavg"")"),202607.0) -> 202607 | AB6: =IFERROR(__xludf.DUMMYFUNCTION("GOOGLEFINANCE(C6,""volume"")"),113356.0) -> 113356 | AC6: Defence | AD6: Moving
A7: AXIT IT LTD | B7: 532395 | C7: AXISCADES | D7: INE555B01013 | E7: Equity | F7: 1 | G7: =IFERROR(__xludf.DUMMYFUNCTION("GOOGLEFINANCE(C7)"),1472.4) -> 1472.4 | H7: 478.5 | I7: =H7*F7 -> 478.5 | J7: =G7*F7 -> 1472.4 | K7: =J7-I7 -> 993.9 | L7: =K7/I7 -> 2.077116 | M7: 1 | N7: =(I7 + (M7 * G7)) / (F7 + M7) -> 975.45 | O7: =G7-N7 -> 496.95 | P7: =O7*F7+M7 -> 497.95 | Q7: =P7/(I7+(G7*M7)) -> 0.25524117 | R7: =IF(Q7 > L7, "Yes", "No") -> No | S7: =Q7-L7 -> -1.8218748 | T7: =IFERROR(__xludf.DUMMYFUNCTION("GOOGLEFINANCE(C7,""pe"")"),63.71) -> 63.71 | U7: =IFERROR(__xludf.DUMMYFUNCTION("GOOGLEFINANCE(C7,""marketcap"")"),6.2696142255E10) -> 62696142255 | V7: =IFERROR(__xludf.DUMMYFUNCTION("GOOGLEFINANCE(C7,""eps"")"),23.14) -> 23.14 | W7: =IFERROR(__xludf.DUMMYFUNCTION("GOOGLEFINANCE(C7,""high52"")"),1779.2) -> 1779.2 | X7: =H7/W7 -> 0.2689411 | Y7: =IFERROR(__xludf.DUMMYFUNCTION("GOOGLEFINANCE(C7,""low52"")"),663.0) -> 663 | Z7: =H7/Y7 -> 0.72171946 | AA7: =IFERROR(__xludf.DUMMYFUNCTION("GOOGLEFINANCE(C7,""volumeavg"")"),131418.0) -> 131418 | AB7: =IFERROR(__xludf.DUMMYFUNCTION("GOOGLEFINANCE(C7,""volume"")"),192126.0) -> 192126 | AC7: Defence | AD7: Moving
A8: Bharat Dynamics Limited | B8: 541143 | C8: NSE:BDL | D8: INE171Z01026 | E8: Equity | F8: 12 | G8: =IFERROR(__xludf.DUMMYFUNCTION("GOOGLEFINANCE(C8)"),1245.0) -> 1245 | H8: 1107 | I8: =H8*F8 -> 13284 | J8: =G8*F8 -> 14940 | K8: =J8-I8 -> 1656 | L8: =K8/I8 -> 0.12466125 | M8: 1 | N8: =(I8 + (M8 * G8)) / (F8 + M8) -> 1117.6154 | O8: =G8-N8 -> 127.38462 | P8: =O8*F8+M8 -> 1529.6154 | Q8: =P8/(I8+(G8*M8)) -> 0.10528016 | R8: =IF(Q8 > L8, "Yes", "No") -> No | S8: =Q8-L8 -> -0.019381091 | T8: =IFERROR(__xludf.DUMMYFUNCTION("GOOGLEFINANCE(C8,""pe"")"),78.65) -> 78.65 | U8: =IFERROR(__xludf.DUMMYFUNCTION("GOOGLEFINANCE(C8,""marketcap"")"),4.56626888351E11) -> 456626888351 | V8: =IFERROR(__xludf.DUMMYFUNCTION("GOOGLEFINANCE(C8,""eps"")"),15.83) -> 15.83 | W8: =IFERROR(__xludf.DUMMYFUNCTION("GOOGLEFINANCE(C8,""high52"")"),2096.6) -> 2096.6 | X8: =H8/W8 -> 0.52799771 | Y8: =IFERROR(__xludf.DUMMYFUNCTION("GOOGLEFINANCE(C8,""low52"")"),907.0) -> 907 | Z8: =H8/Y8 -> 1.2205072 | AA8: =IFERROR(__xludf.DUMMYFUNCTION("GOOGLEFINANCE(C8,""volumeavg"")"),1528256.0) -> 1528256 | AB8: =IFERROR(__xludf.DUMMYFUNCTION("GOOGLEFINANCE(C8,""volume"")"),661203.0) -> 661203 | AC8: Defence | AD8: Moving
A9: BHARAT ELECT | B9: 500049 | C9: NSE:BEL | D9: INE263A01024 | E9: Equity | F9: 10 | G9: =IFERROR(__xludf.DUMMYFUNCTION("GOOGLEFINANCE(C9)"),431.15) -> 431.15 | H9: 208.43 | I9: =H9*F9 -> 2084.3 | J9: =G9*F9 -> 4311.5 | K9: =J9-I9 -> 2227.2 | L9: =K9/I9 -> 1.0685602 | M9: 1 | N9: =(I9 + (M9 * G9)) / (F9 + M9) -> 228.67727 | O9: =G9-N9 -> 202.47273 | P9: =O9*F9+M9 -> 2025.7273 | Q9: =P9/(I9+(G9*M9)) -> 0.80531407 | R9: =IF(Q9 > L9, "Yes", "No") -> No | S9: =Q9-L9 -> -0.26324612 | T9: =IFERROR(__xludf.DUMMYFUNCTION("GOOGLEFINANCE(C9,""pe"")"),52.84) -> 52.84 | U9: =IFERROR(__xludf.DUMMYFUNCTION("GOOGLEFINANCE(C9,""marketcap"")"),3.15197636283E12) -> 3151976362830 | V9: =IFERROR(__xludf.DUMMYFUNCTION("GOOGLEFINANCE(C9,""eps"")"),8.16) -> 8.16 | W9: =IFERROR(__xludf.DUMMYFUNCTION("GOOGLEFINANCE(C9,""high52"")"),461.65) -> 461.65 | X9: =H9/W9 -> 0.45148922 | Y9: =IFERROR(__xludf.DUMMYFUNCTION("GOOGLEFINANCE(C9,""low52"")"),243.5) -> 243.5 | Z9: =H9/Y9 -> 0.85597536 | AA9: =IFERROR(__xludf.DUMMYFUNCTION("GOOGLEFINANCE(C9,""volumeavg"")"),1.837715E7) -> 18377150 | AB9: =IFERROR(__xludf.DUMMYFUNCTION("GOOGLEFINANCE(C9,""volume"")"),6166968.0) -> 6166968 | AC9: Defence | AD9: Moving
A10: Bharti Hexacom Limited | B10: 544162 | C10: BHARTIHEXA | D10: INE343G01021 | E10: Equity | F10: 26 | G10: =IFERROR(__xludf.DUMMYFUNCTION("GOOGLEFINANCE(C10)"),1662.6) -> 1662.6 | H10: 570 | I10: =H10*F10 -> 14820 | J10: =G10*F10 -> 43227.6 | K10: =J10-I10 -> 28407.6 | L10: =K10/I10 -> 1.9168421 | M10: 1 | N10: =(I10 + (M10 * G10)) / (F10 + M10) -> 610.46667 | O10: =G10-N10 -> 1052.1333 | P10: =O10*F10+M10 -> 27356.467 | Q10: =P10/(I10+(G10*M10)) -> 1.6597179 | R10: =IF(Q10 > L10, "Yes", "No") -> No | S10: =Q10-L10 -> -0.25712418 | T10: =IFERROR(__xludf.DUMMYFUNCTION("GOOGLEFINANCE(C10,""pe"")"),47.46) -> 47.46 | U10: =IFERROR(__xludf.DUMMYFUNCTION("GOOGLEFINANCE(C10,""marketcap"")"),8.32099809165E11) -> 832099809165 | V10: =IFERROR(__xludf.DUMMYFUNCTION("GOOGLEFINANCE(C10,""eps"")"),35.09) -> 35.09 | W10: =IFERROR(__xludf.DUMMYFUNCTION("GOOGLEFINANCE(C10,""high52"")"),2052.9) -> 2052.9 | X10: =H10/W10 -> 0.277656 | Y10: =IFERROR(__xludf.DUMMYFUNCTION("GOOGLEFINANCE(C10,""low52"")"),1234.0) -> 1234 | Z10: =H10/Y10 -> 0.46191248 | AA10: =IFERROR(__xludf.DUMMYFUNCTION("GOOGLEFINANCE(C10,""volumeavg"")"),189016.0) -> 189016 | AB10: =IFERROR(__xludf.DUMMYFUNCTION("GOOGLEFINANCE(C10,""volume"")"),24443.0) -> 24443 | AC10: Technology | AD10: Moving
A11: CG POWER | B11: 500093 | C11: CGPOWER | D11: INE067A01029 | E11: Equity | F11: 5 | G11: =IFERROR(__xludf.DUMMYFUNCTION("GOOGLEFINANCE(C11)"),715.7) -> 715.7 | H11: 633.8 | I11: =H11*F11 -> 3169 | J11: =G11*F11 -> 3578.5 | K11: =J11-I11 -> 409.5 | L11: =K11/I11 -> 0.12922057 | M11: 1 | N11: =(I11 + (M11 * G11)) / (F11 + M11) -> 647.45 | O11: =G11-N11 -> 68.25 | P11: =O11*F11+M11 -> 342.25 | Q11: =P11/(I11+(G11*M11)) -> 0.088102041 | R11: =IF(Q11 > L11, "Yes", "No") -> No | S11: =Q11-L11 -> -0.041118533 | T11: =IFERROR(__xludf.DUMMYFUNCTION("GOOGLEFINANCE(C11,""pe"")"),99.75) -> 99.75 | U11: =IFERROR(__xludf.DUMMYFUNCTION("GOOGLEFINANCE(C11,""marketcap"")"),1.127629832E12) -> 1127629832000 | V11: =IFERROR(__xludf.DUMMYFUNCTION("GOOGLEFINANCE(C11,""eps"")"),7.17) -> 7.17 | W11: =IFERROR(__xludf.DUMMYFUNCTION("GOOGLEFINANCE(C11,""high52"")"),797.55) -> 797.55 | X11: =H11/W11 -> 0.79468372 | Y11: =IFERROR(__xludf.DUMMYFUNCTION("GOOGLEFINANCE(C11,""low52"")"),517.7) -> 517.7 | Z11: =H11/Y11 -> 1.2242612 | AA11: =IFERROR(__xludf.DUMMYFUNCTION("GOOGLEFINANCE(C11,""volumeavg"")"),4211897.0) -> 4211897 | AB11: =IFERROR(__xludf.DUMMYFUNCTION("GOOGLEFINANCE(C11,""volume"")"),853767.0) -> 853767 | AC11: Technology | AD11: Moving
A12: Cochin Shipyard Limited | B12: 540678 | C12: COCHINSHIP | D12: INE704P01025 | E12: Equity | F12: 13 | G12: =IFERROR(__xludf.DUMMYFUNCTION("GOOGLEFINANCE(C12)"),1486.0) -> 1486 | H12: 1624.87 | I12: =H12*F12 -> 21123.31 | J12: =G12*F12 -> 19318 | K12: =J12-I12 -> -1805.31 | L12: =K12/I12 -> -0.085465299 | M12: 1 | N12: =(I12 + (M12 * G12)) / (F12 + M12) -> 1614.9507 | O12: =G12-N12 -> -128.95071 | P12: =O12*F12+M12 -> -1675.3593 | Q12: =P12/(I12+(G12*M12)) -> -0.074100416 | R12: =IF(Q12 > L12, "Yes", "No") -> Yes | S12: =Q12-L12 -> 0.011364882 | T12: =IFERROR(__xludf.DUMMYFUNCTION("GOOGLEFINANCE(C12,""pe"")"),53.74) -> 53.74 | U12: =IFERROR(__xludf.DUMMYFUNCTION("GOOGLEFINANCE(C12,""marketcap"")"),3.90990523494E11) -> 390990523494 | V12: =IFERROR(__xludf.DUMMYFUNCTION("GOOGLEFINANCE(C12,""eps"")"),27.65) -> 27.65 | W12: =IFERROR(__xludf.DUMMYFUNCTION("GOOGLEFINANCE(C12,""high52"")"),2545.0) -> 2545 | X12: =H12/W12 -> 0.6384558 | Y12: =IFERROR(__xludf.DUMMYFUNCTION("GOOGLEFINANCE(C12,""low52"")"),1199.6) -> 1199.6 | Z12: =H12/Y12 -> 1.3545098 | AA12: =IFERROR(__xludf.DUMMYFUNCTION("GOOGLEFINANCE(C12,""volumeavg"")"),873791.0) -> 873791 | AB12: =IFERROR(__xludf.DUMMYFUNCTION("GOOGLEFINANCE(C12,""volume"")"),212737.0) -> 212737 | AC12: Defence | AD12: Moving
A13: CPSE ETF GROWTH | B13: 538057 | C13: CPSEETF | D13: INF457M01133 | E13: ETF | F13: 23 | G13: =IFERROR(__xludf.DUMMYFUNCTION("GOOGLEFINANCE(C13)"),101.74) -> 101.74 | H13: 95.89 | I13: =H13*F13 -> 2205.47 | J13: =G13*F13 -> 2340.02 | K13: =J13-I13 -> 134.55 | L13: =K13/I13 -> 0.061007404 | M13: 1 | N13: =(I13 + (M13 * G13)) / (F13 + M13) -> 96.13375 | O13: =G13-N13 -> 5.60625 | P13: =O13*F13+M13 -> 129.94375 | Q13: =P13/(I13+(G13*M13)) -> 0.056320729 | R13: =IF(Q13 > L13, "Yes", "No") -> No | S13: =Q13-L13 -> -0.004686675 | T13: =IFERROR(__xludf.DUMMYFUNCTION("GOOGLEFINANCE(C13,""pe"")"),"#N/A") -> #N/A | U13: =IFERROR(__xludf.DUMMYFUNCTION("GOOGLEFINANCE(C13,""marketcap"")"),"#N/A") -> #N/A | V13: =IFERROR(__xludf.DUMMYFUNCTION("GOOGLEFINANCE(C13,""eps"")"),"#N/A") -> #N/A | W13: =IFERROR(__xludf.DUMMYFUNCTION("GOOGLEFINANCE(C13,""high52"")"),105.0) -> 105 | X13: =H13/W13 -> 0.9132381 | Y13: =IFERROR(__xludf.DUMMYFUNCTION("GOOGLEFINANCE(C13,""low52"")"),74.9) -> 74.9 | Z13: =H13/Y13 -> 1.2802403 | AA13: =IFERROR(__xludf.DUMMYFUNCTION("GOOGLEFINANCE(C13,""volumeavg"")"),3146129.0) -> 3146129 | AB13: =IFERROR(__xludf.DUMMYFUNCTION("GOOGLEFINANCE(C13,""volume"")"),2196305.0) -> 2196305 | AC13: Others | AD13: Moving
A14: DREDG CORP I | B14: 523618 | C14: DREDGECORP | D14: INE506A01018 | E14: Equity | F14: 3 | G14: =IFERROR(__xludf.DUMMYFUNCTION("GOOGLEFINANCE(C14)"),913.8) -> 913.8 | H14: 791.08 | I14: =H14*F14 -> 2373.24 | J14: =G14*F14 -> 2741.4 | K14: =J14-I14 -> 368.16 | L14: =K14/I14 -> 0.1551297 | M14: 1 | N14: =(I14 + (M14 * G14)) / (F14 + M14) -> 821.76 | O14: =G14-N14 -> 92.04 | P14: =O14*F14+M14 -> 277.12 | Q14: =P14/(I14+(G14*M14)) -> 0.084306854 | R14: =IF(Q14 > L14, "Yes", "No") -> No | S14: =Q14-L14 -> -0.070822843 | T14: =IFERROR(__xludf.DUMMYFUNCTION("GOOGLEFINANCE(C14,""pe"")"),"#N/A") -> #N/A | U14: =IFERROR(__xludf.DUMMYFUNCTION("GOOGLEFINANCE(C14,""marketcap"")"),2.5569600341E10) -> 25569600341 | V14: =IFERROR(__xludf.DUMMYFUNCTION("GOOGLEFINANCE(C14,""eps"")"),-21.7) -> -21.7 | W14: =IFERROR(__xludf.DUMMYFUNCTION("GOOGLEFINANCE(C14,""high52"")"),1245.0) -> 1245 | X14: =H14/W14 -> 0.63540562 | Y14: =IFERROR(__xludf.DUMMYFUNCTION("GOOGLEFINANCE(C14,""low52"")"),495.0) -> 495 | Z14: =H14/Y14 -> 1.5981414 | AA14: =IFERROR(__xludf.DUMMYFUNCTION("GOOGLEFINANCE(C14,""volumeavg"")"),587846.0) -> 587846 | AB14: =IFERROR(__xludf.DUMMYFUNCTION("GOOGLEFINANCE(C14,""volume"")"),72276.0) -> 72276 | AC14: PSU | AD14: Moving
A15: GARDEN REACH SHIP&ENG LTD | B15: 542011 | C15: GRSE | D15: INE382Z01011 | E15: Equity | F15: 2 | G15: =IFERROR(__xludf.DUMMYFUNCTION("GOOGLEFINANCE(C15)"),2399.6) -> 2399.6 | H15: 1218.5 | I15: =H15*F15 -> 2437 | J15: =G15*F15 -> 4799.2 | K15: =J15-I15 -> 2362.2 | L15: =K15/I15 -> 0.96930652 | M15: 1 | N15: =(I15 + (M15 * G15)) / (F15 + M15) -> 1612.2 | O15: =G15-N15 -> 787.4 | P15: =O15*F15+M15 -> 1575.8 | Q15: =P15/(I15+(G15*M15)) -> 0.32580739 | R15: =IF(Q15 > L15, "Yes", "No") -> No | S15: =Q15-L15 -> -0.64349914 | T15: =IFERROR(__xludf.DUMMYFUNCTION("GOOGLEFINANCE(C15,""pe"")"),39.87) -> 39.87 | U15: =IFERROR(__xludf.DUMMYFUNCTION("GOOGLEFINANCE(C15,""marketcap"")"),2.74706401565E11) -> 274706401565 | V15: =IFERROR(__xludf.DUMMYFUNCTION("GOOGLEFINANCE(C15,""eps"")"),60.15) -> 60.15 | W15: =IFERROR(__xludf.DUMMYFUNCTION("GOOGLEFINANCE(C15,""high52"")"),3538.4) -> 3538.4 | X15: =H15/W15 -> 0.34436468 | Y15: =IFERROR(__xludf.DUMMYFUNCTION("GOOGLEFINANCE(C15,""low52"")"),1184.9) -> 1184.9 | Z15: =H15/Y15 -> 1.0283568 | AA15: =IFERROR(__xludf.DUMMYFUNCTION("GOOGLEFINANCE(C15,""volumeavg"")"),1083030.0) -> 1083030 | AB15: =IFERROR(__xludf.DUMMYFUNCTION("GOOGLEFINANCE(C15,""volume"")"),248602.0) -> 248602 | AC15: Defence | AD15: Moving
A16: GREENPOWER | B16: 533263 | C16: GREENPOWER | D16: INE999K01014 | E16: Equity | F16: 93 | G16: =IFERROR(__xludf.DUMMYFUNCTION("GOOGLEFINANCE(C16)"),9.77) -> 9.77 | H16: 11.87 | I16: =H16*F16 -> 1103.91 | J16: =G16*F16 -> 908.61 | K16: =J16-I16 -> -195.3 | L16: =K16/I16 -> -0.1769166 | M16: 1 | N16: =(I16 + (M16 * G16)) / (F16 + M16) -> 11.84766 | O16: =G16-N16 -> -2.0776596 | P16: =O16*F16+M16 -> -192.22234 | Q16: =P16/(I16+(G16*M16)) -> -0.17260105 | R16: =IF(Q16 > L16, "Yes", "No") -> Yes | S16: =Q16-L16 -> 0.0043155437 | T16: =IFERROR(__xludf.DUMMYFUNCTION("GOOGLEFINANCE(C16,""pe"")"),16.79) -> 16.79 | U16: =IFERROR(__xludf.DUMMYFUNCTION("GOOGLEFINANCE(C16,""marketcap"")"),1.1472242866E10) -> 11472242866 | V16: =IFERROR(__xludf.DUMMYFUNCTION("GOOGLEFINANCE(C16,""eps"")"),0.58) -> 0.58 | W16: =IFERROR(__xludf.DUMMYFUNCTION("GOOGLEFINANCE(C16,""high52"")"),15.81) -> 15.81 | X16: =H16/W16 -> 0.75079064 | Y16: =IFERROR(__xludf.DUMMYFUNCTION("GOOGLEFINANCE(C16,""low52"")"),9.68) -> 9.68 | Z16: =H16/Y16 -> 1.2262397 | AA16: =IFERROR(__xludf.DUMMYFUNCTION("GOOGLEFINANCE(C16,""volumeavg"")"),2969181.0) -> 2969181 | AB16: =IFERROR(__xludf.DUMMYFUNCTION("GOOGLEFINANCE(C16,""volume"")"),1402112.0) -> 1402112 | AC16: Green Energy | AD16: Moving
A17: HAL | B17: 541154 | C17: NSE:HAL | D17: INE066F01020 | E17: Equity | F17: 3 | G17: =IFERROR(__xludf.DUMMYFUNCTION("GOOGLEFINANCE(C17)"),3957.1) -> 3957.1 | H17: 4388.33 | I17: =H17*F17 -> 13164.99 | J17: =G17*F17 -> 11871.3 | K17: =J17-I17 -> -1293.69 | L17: =K17/I17 -> -0.09826745 | M17: 1 | N17: =(I17 + (M17 * G17)) / (F17 + M17) -> 4280.5225 | O17: =G17-N17 -> -323.4225 | P17: =O17*F17+M17 -> -969.2675 | Q17: =P17/(I17+(G17*M17)) -> -0.056609181 | R17: =IF(Q17 > L17, "Yes", "No") -> Yes | S17: =Q17-L17 -> 0.041658269 | T17: =IFERROR(__xludf.DUMMYFUNCTION("GOOGLEFINANCE(C17,""pe"")"),29.77) -> 29.77 | U17: =IFERROR(__xludf.DUMMYFUNCTION("GOOGLEFINANCE(C17,""marketcap"")"),2.646342675E12) -> 2646342675000 | V17: =IFERROR(__xludf.DUMMYFUNCTION("GOOGLEFINANCE(C17,""eps"")"),133.03) -> 133.03 | W17: =IFERROR(__xludf.DUMMYFUNCTION("GOOGLEFINANCE(C17,""high52"")"),5165.0) -> 5165 | X17: =H17/W17 -> 0.84962827 | Y17: =IFERROR(__xludf.DUMMYFUNCTION("GOOGLEFINANCE(C17,""low52"")"),3046.05) -> 3046.05 | Z17: =H17/Y17 -> 1.4406625 | AA17: =IFERROR(__xludf.DUMMYFUNCTION("GOOGLEFINANCE(C17,""volumeavg"")"),1651741.0) -> 1651741 | AB17: =IFERROR(__xludf.DUMMYFUNCTION("GOOGLEFINANCE(C17,""volume"")"),943077.0) -> 943077 | AC17: Defence | AD17: Moving
A18: HATHWAY CAB | B18: 533162 | C18: HATHWAY | D18: INE982F01036 | E18: Equity | F18: 5 | G18: =IFERROR(__xludf.DUMMYFUNCTION("GOOGLEFINANCE(C18)"),10.76) -> 10.76 | H18: 24.99 | I18: =H18*F18 -> 124.95 | J18: =G18*F18 -> 53.8 | K18: =J18-I18 -> -71.15 | L18: =K18/I18 -> -0.56942777 | M18: 1 | N18: =(I18 + (M18 * G18)) / (F18 + M18) -> 22.618333 | O18: =G18-N18 -> -11.858333 | P18: =O18*F18+M18 -> -58.291667 | Q18: =P18/(I18+(G18*M18)) -> -0.42953111 | R18: =IF(Q18 > L18, "Yes", "No") -> Yes | S18: =Q18-L18 -> 0.13989666 | T18: =IFERROR(__xludf.DUMMYFUNCTION("GOOGLEFINANCE(C18,""pe"")"),18.23) -> 18.23 | U18: =IFERROR(__xludf.DUMMYFUNCTION("GOOGLEFINANCE(C18,""marketcap"")"),1.9046319445E10) -> 19046319445 | V18: =IFERROR(__xludf.DUMMYFUNCTION("GOOGLEFINANCE(C18,""eps"")"),0.59) -> 0.59 | W18: =IFERROR(__xludf.DUMMYFUNCTION("GOOGLEFINANCE(C18,""high52"")"),17.98) -> 17.98 | X18: =H18/W18 -> 1.3898776 | Y18: =IFERROR(__xludf.DUMMYFUNCTION("GOOGLEFINANCE(C18,""low52"")"),9.91) -> 9.91 | Z18: =H18/Y18 -> 2.5216953 | AA18: =IFERROR(__xludf.DUMMYFUNCTION("GOOGLEFINANCE(C18,""volumeavg"")"),2609507.0) -> 2609507 | AB18: =IFERROR(__xludf.DUMMYFUNCTION("GOOGLEFINANCE(C18,""volume"")"),1237608.0) -> 1237608 | AC18: Others | AD18: Non Moving
A19: HBL Engineering Limited | B19: 517271 | C19: HBLENGINE | D19: INE292B01021 | E19: Equity | F19: 4 | G19: =IFERROR(__xludf.DUMMYFUNCTION("GOOGLEFINANCE(C19)"),698.85) -> 698.85 | H19: 568.75 | I19: =H19*F19 -> 2275 | J19: =G19*F19 -> 2795.4 | K19: =J19-I19 -> 520.4 | L19: =K19/I19 -> 0.22874725 | M19: 1 | N19: =(I19 + (M19 * G19)) / (F19 + M19) -> 594.77 | O19: =G19-N19 -> 104.08 | P19: =O19*F19+M19 -> 417.32 | Q19: =P19/(I19+(G19*M19)) -> 0.14032988 | R19: =IF(Q19 > L19, "Yes", "No") -> No | S19: =Q19-L19 -> -0.088417377 | T19: =IFERROR(__xludf.DUMMYFUNCTION("GOOGLEFINANCE(C19,""pe"")"),55.29) -> 55.29 | U19: =IFERROR(__xludf.DUMMYFUNCTION("GOOGLEFINANCE(C19,""marketcap"")"),1.937052606E11) -> 193705260600 | V19: =IFERROR(__xludf.DUMMYFUNCTION("GOOGLEFINANCE(C19,""eps"")"),11.81) -> 11.81 | W19: =IFERROR(__xludf.DUMMYFUNCTION("GOOGLEFINANCE(C19,""high52"")"),1122.0) -> 1122 | X19: =H19/W19 -> 0.50690731 | Y19: =IFERROR(__xludf.DUMMYFUNCTION("GOOGLEFINANCE(C19,""low52"")"),405.0) -> 405 | Z19: =H19/Y19 -> 1.404321 | AA19: =IFERROR(__xludf.DUMMYFUNCTION("GOOGLEFINANCE(C19,""volumeavg"")"),2134989.0) -> 2134989 | AB19: =IFERROR(__xludf.DUMMYFUNCTION("GOOGLEFINANCE(C19,""volume"")"),520973.0) -> 520973 | AC19: Technology | AD19: Moving
A20: ICICIPRAMC - BHARATIWIN | B20: 540787 | C20: ICICIB22 | D20: INF109KB15Y7 | E20: ETF | F20: 18 | G20: =IFERROR(__xludf.DUMMYFUNCTION("GOOGLEFINANCE(C20)"),126.26) -> 126.26 | H20: 109.91 | I20: =H20*F20 -> 1978.38 | J20: =G20*F20 -> 2272.68 | K20: =J20-I20 -> 294.3 | L20: =K20/I20 -> 0.14875807 | M20: 1 | N20: =(I20 + (M20 * G20)) / (F20 + M20) -> 110.77053 | O20: =G20-N20 -> 15.489474 | P20: =O20*F20+M20 -> 279.81053 | Q20: =P20/(I20+(G20*M20)) -> 0.13294935 | R20: =IF(Q20 > L20, "Yes", "No") -> No | S20: =Q20-L20 -> -0.015808722 | T20: =IFERROR(__xludf.DUMMYFUNCTION("GOOGLEFINANCE(C20,""pe"")"),"#N/A") -> #N/A | U20: =IFERROR(__xludf.DUMMYFUNCTION("GOOGLEFINANCE(C20,""marketcap"")"),"#N/A") -> #N/A | V20: =IFERROR(__xludf.DUMMYFUNCTION("GOOGLEFINANCE(C20,""eps"")"),"#N/A") -> #N/A | W20: =IFERROR(__xludf.DUMMYFUNCTION("GOOGLEFINANCE(C20,""high52"")"),129.98) -> 129.98 | X20: =H20/W20 -> 0.84559163 | Y20: =IFERROR(__xludf.DUMMYFUNCTION("GOOGLEFINANCE(C20,""low52"")"),93.02) -> 93.02 | Z20: =H20/Y20 -> 1.1815739 | AA20: =IFERROR(__xludf.DUMMYFUNCTION("GOOGLEFINANCE(C20,""volumeavg"")"),627414.0) -> 627414 | AB20: =IFERROR(__xludf.DUMMYFUNCTION("GOOGLEFINANCE(C20,""volume"")"),208997.0) -> 208997 | AC20: Others | AD20: Moving
A21: ICICIPRUGETF | B21: 533244 | C21: GOLDIETF | D21: INF109KC1NT3 | E21: ETF | F21: 28 | G21: =IFERROR(__xludf.DUMMYFUNCTION("GOOGLEFINANCE(C21)"),135.87) -> 135.87 | H21: 61.14 | I21: =H21*F21 -> 1711.92 | J21: =G21*F21 -> 3804.36 | K21: =J21-I21 -> 2092.44 | L21: =K21/I21 -> 1.2222767 | M21: 1 | N21: =(I21 + (M21 * G21)) / (F21 + M21) -> 63.716897 | O21: =G21-N21 -> 72.153103 | P21: =O21*F21+M21 -> 2021.2869 | Q21: =P21/(I21+(G21*M21)) -> 1.0938943 | R21: =IF(Q21 > L21, "Yes", "No") -> No | S21: =Q21-L21 -> -0.12838247 | T21: =IFERROR(__xludf.DUMMYFUNCTION("GOOGLEFINANCE(C21,""pe"")"),"#N/A") -> #N/A | U21: =IFERROR(__xludf.DUMMYFUNCTION("GOOGLEFINANCE(C21,""marketcap"")"),"#N/A") -> #N/A | V21: =IFERROR(__xludf.DUMMYFUNCTION("GOOGLEFINANCE(C21,""eps"")"),"#N/A") -> #N/A | W21: =IFERROR(__xludf.DUMMYFUNCTION("GOOGLEFINANCE(C21,""high52"")"),158.0) -> 158 | X21: =H21/W21 -> 0.38696203 | Y21: =IFERROR(__xludf.DUMMYFUNCTION("GOOGLEFINANCE(C21,""low52"")"),69.71) -> 69.71 | Z21: =H21/Y21 -> 0.87706211 | AA21: =IFERROR(__xludf.DUMMYFUNCTION("GOOGLEFINANCE(C21,""volumeavg"")"),1.9770733E7) -> 19770733 | AB21: =IFERROR(__xludf.DUMMYFUNCTION("GOOGLEFINANCE(C21,""volume"")"),4881148.0) -> 4881148 | AC21: Others | AD21: Moving
A22: IDFC FIRST BANK LTD. | B22: 539437 | C22: IDFCFIRSTB | D22: INE092T01019 | E22: Equity | F22: 53 | G22: =IFERROR(__xludf.DUMMYFUNCTION("GOOGLEFINANCE(C22)"),68.73) -> 68.73 | H22: 69.96 | I22: =H22*F22 -> 3707.88 | J22: =G22*F22 -> 3642.69 | K22: =J22-I22 -> -65.19 | L22: =K22/I22 -> -0.017581475 | M22: 1 | N22: =(I22 + (M22 * G22)) / (F22 + M22) -> 69.937222 | O22: =G22-N22 -> -1.2072222 | P22: =O22*F22+M22 -> -62.982778 | Q22: =P22/(I22+(G22*M22)) -> -0.016677067 | R22: =IF(Q22 > L22, "Yes", "No") -> Yes | S22: =Q22-L22 -> 0.00090440819 | T22: =IFERROR(__xludf.DUMMYFUNCTION("GOOGLEFINANCE(C22,""pe"")"),33.45) -> 33.45 | U22: =IFERROR(__xludf.DUMMYFUNCTION("GOOGLEFINANCE(C22,""marketcap"")"),5.03565401602E11) -> 503565401602 | V22: =IFERROR(__xludf.DUMMYFUNCTION("GOOGLEFINANCE(C22,""eps"")"),2.06) -> 2.06 | W22: =IFERROR(__xludf.DUMMYFUNCTION("GOOGLEFINANCE(C22,""high52"")"),87.0) -> 87 | X22: =H22/W22 -> 0.80413793 | Y22: =IFERROR(__xludf.DUMMYFUNCTION("GOOGLEFINANCE(C22,""low52"")"),52.46) -> 52.46 | Z22: =H22/Y22 -> 1.3335875 | AA22: =IFERROR(__xludf.DUMMYFUNCTION("GOOGLEFINANCE(C22,""volumeavg"")"),4.1817099E7) -> 41817099 | AB22: =IFERROR(__xludf.DUMMYFUNCTION("GOOGLEFINANCE(C22,""volume"")"),1.41406091E8) -> 141406091 | AC22: Technology | AD22: Moving
A23: Indian Railway Catering and To | B23: 542830 | C23: IRCTC | D23: INE335Y01020 | E23: Equity | F23: 4 | G23: =IFERROR(__xludf.DUMMYFUNCTION("GOOGLEFINANCE(C23)"),630.15) -> 630.15 | H23: 866.23 | I23: =H23*F23 -> 3464.92 | J23: =G23*F23 -> 2520.6 | K23: =J23-I23 -> -944.32 | L23: =K23/I23 -> -0.27253732 | M23: 1 | N23: =(I23 + (M23 * G23)) / (F23 + M23) -> 819.014 | O23: =G23-N23 -> -188.864 | P23: =O23*F23+M23 -> -754.456 | Q23: =P23/(I23+(G23*M23)) -> -0.18423519 | R23: =IF(Q23 > L23, "Yes", "No") -> Yes | S23: =Q23-L23 -> 0.088302127 | T23: =IFERROR(__xludf.DUMMYFUNCTION("GOOGLEFINANCE(C23,""pe"")"),35.37) -> 35.37 | U23: =IFERROR(__xludf.DUMMYFUNCTION("GOOGLEFINANCE(C23,""marketcap"")"),5.04119956516E11) -> 504119956516 | V23: =IFERROR(__xludf.DUMMYFUNCTION("GOOGLEFINANCE(C23,""eps"")"),17.82) -> 17.82 | W23: =IFERROR(__xludf.DUMMYFUNCTION("GOOGLEFINANCE(C23,""high52"")"),820.25) -> 820.25 | X23: =H23/W23 -> 1.0560561 | Y23: =IFERROR(__xludf.DUMMYFUNCTION("GOOGLEFINANCE(C23,""low52"")"),596.0) -> 596 | Z23: =H23/Y23 -> 1.453406 | AA23: =IFERROR(__xludf.DUMMYFUNCTION("GOOGLEFINANCE(C23,""volumeavg"")"),1643006.0) -> 1643006 | AB23: =IFERROR(__xludf.DUMMYFUNCTION("GOOGLEFINANCE(C23,""volume"")"),1330692.0) -> 1330692 | AC23: PSU | AD23: Moving
A24: Indian Railway Finance | B24: 543257 | C24: IRFC | D24: INE053F01010 | E24: Equity | F24: 24 | G24: =IFERROR(__xludf.DUMMYFUNCTION("GOOGLEFINANCE(C24)"),110.06) -> 110.06 | H24: 151.1 | I24: =H24*F24 -> 3626.4 | J24: =G24*F24 -> 2641.44 | K24: =J24-I24 -> -984.96 | L24: =K24/I24 -> -0.27160821 | M24: 1 | N24: =(I24 + (M24 * G24)) / (F24 + M24) -> 149.4584 | O24: =G24-N24 -> -39.3984 | P24: =O24*F24+M24 -> -944.5616 | Q24: =P24/(I24+(G24*M24)) -> -0.25279585 | R24: =IF(Q24 > L24, "Yes", "No") -> Yes | S24: =Q24-L24 -> 0.018812352 | T24: =IFERROR(__xludf.DUMMYFUNCTION("GOOGLEFINANCE(C24,""pe"")"),20.51) -> 20.51 | U24: =IFERROR(__xludf.DUMMYFUNCTION("GOOGLEFINANCE(C24,""marketcap"")"),1.438189565381E12) -> 1438189565381 | V24: =IFERROR(__xludf.DUMMYFUNCTION("GOOGLEFINANCE(C24,""eps"")"),5.37) -> 5.37 | W24: =IFERROR(__xludf.DUMMYFUNCTION("GOOGLEFINANCE(C24,""high52"")"),148.95) -> 148.95 | X24: =H24/W24 -> 1.0144344 | Y24: =IFERROR(__xludf.DUMMYFUNCTION("GOOGLEFINANCE(C24,""low52"")"),108.04) -> 108.04 | Z24: =H24/Y24 -> 1.3985561 | AA24: =IFERROR(__xludf.DUMMYFUNCTION("GOOGLEFINANCE(C24,""volumeavg"")"),1.4246528E7) -> 14246528 | AB24: =IFERROR(__xludf.DUMMYFUNCTION("GOOGLEFINANCE(C24,""volume"")"),6343574.0) -> 6343574 | AC24: PSU | AD24: Moving
A25: IRCON International Ltd | B25: 541956 | C25: IRCON | D25: INE962Y01021 | E25: Equity | F25: 10 | G25: =IFERROR(__xludf.DUMMYFUNCTION("GOOGLEFINANCE(C25)"),147.31) -> 147.31 | H25: 207.6 | I25: =H25*F25 -> 2076 | J25: =G25*F25 -> 1473.1 | K25: =J25-I25 -> -602.9 | L25: =K25/I25 -> -0.29041426 | M25: 1 | N25: =(I25 + (M25 * G25)) / (F25 + M25) -> 202.11909 | O25: =G25-N25 -> -54.809091 | P25: =O25*F25+M25 -> -547.09091 | Q25: =P25/(I25+(G25*M25)) -> -0.24607046 | R25: =IF(Q25 > L25, "Yes", "No") -> Yes | S25: =Q25-L25 -> 0.044343801 | T25: =IFERROR(__xludf.DUMMYFUNCTION("GOOGLEFINANCE(C25,""pe"")"),22.54) -> 22.54 | U25: =IFERROR(__xludf.DUMMYFUNCTION("GOOGLEFINANCE(C25,""marketcap"")"),1.38613223196E11) -> 138613223196 | V25: =IFERROR(__xludf.DUMMYFUNCTION("GOOGLEFINANCE(C25,""eps"")"),6.53) -> 6.53 | W25: =IFERROR(__xludf.DUMMYFUNCTION("GOOGLEFINANCE(C25,""high52"")"),225.52) -> 225.52 | X25: =H25/W25 -> 0.9205392 | Y25: =IFERROR(__xludf.DUMMYFUNCTION("GOOGLEFINANCE(C25,""low52"")"),134.24) -> 134.24 | Z25: =H25/Y25 -> 1.5464839 | AA25: =IFERROR(__xludf.DUMMYFUNCTION("GOOGLEFINANCE(C25,""volumeavg"")"),2632347.0) -> 2632347 | AB25: =IFERROR(__xludf.DUMMYFUNCTION("GOOGLEFINANCE(C25,""volume"")"),545536.0) -> 545536 | AC25: PSU | AD25: Moving
A26: IWIND ENERGY | B26: 532894 | C26: INDOWIND | D26: INE227G01018 | E26: Equity | F26: 106 | G26: =IFERROR(__xludf.DUMMYFUNCTION("GOOGLEFINANCE(C26)"),9.71) -> 9.71 | H26: 21.96 | I26: =H26*F26 -> 2327.76 | J26: =G26*F26 -> 1029.26 | K26: =J26-I26 -> -1298.5 | L26: =K26/I26 -> -0.55783242 | M26: 1 | N26: =(I26 + (M26 * G26)) / (F26 + M26) -> 21.845514 | O26: =G26-N26 -> -12.135514 | P26: =O26*F26+M26 -> -1285.3645 | Q26: =P26/(I26+(G26*M26)) -> -0.54989561 | R26: =IF(Q26 > L26, "Yes", "No") -> Yes | S26: =Q26-L26 -> 0.0079368149 | T26: =IFERROR(__xludf.DUMMYFUNCTION("GOOGLEFINANCE(C26,""pe"")"),41.36) -> 41.36 | U26: =IFERROR(__xludf.DUMMYFUNCTION("GOOGLEFINANCE(C26,""marketcap"")"),1.563330397E9) -> 1563330397 | V26: =IFERROR(__xludf.DUMMYFUNCTION("GOOGLEFINANCE(C26,""eps"")"),0.23) -> 0.23 | W26: =IFERROR(__xludf.DUMMYFUNCTION("GOOGLEFINANCE(C26,""high52"")"),23.69) -> 23.69 | X26: =H26/W26 -> 0.92697341 | Y26: =IFERROR(__xludf.DUMMYFUNCTION("GOOGLEFINANCE(C26,""low52"")"),9.61) -> 9.61 | Z26: =H26/Y26 -> 2.2851197 | AA26: =IFERROR(__xludf.DUMMYFUNCTION("GOOGLEFINANCE(C26,""volumeavg"")"),1437899.0) -> 1437899 | AB26: =IFERROR(__xludf.DUMMYFUNCTION("GOOGLEFINANCE(C26,""volume"")"),326049.0) -> 326049 | AC26: Green Energy | AD26: Moving
A27: KPIT Technologies Ltd | B27: 542651 | C27: KPITTECH | D27: INE04I401011 | E27: Equity | F27: 7 | G27: =IFERROR(__xludf.DUMMYFUNCTION("GOOGLEFINANCE(C27)"),772.9) -> 772.9 | H27: 1296.71 | I27: =H27*F27 -> 9076.97 | J27: =G27*F27 -> 5410.3 | K27: =J27-I27 -> -3666.67 | L27: =K27/I27 -> -0.40395308 | M27: 1 | N27: =(I27 + (M27 * G27)) / (F27 + M27) -> 1231.2338 | O27: =G27-N27 -> -458.33375 | P27: =O27*F27+M27 -> -3207.3362 | Q27: =P27/(I27+(G27*M27)) -> -0.32562219 | R27: =IF(Q27 > L27, "Yes", "No") -> Yes | S27: =Q27-L27 -> 0.07833089 | T27: =IFERROR(__xludf.DUMMYFUNCTION("GOOGLEFINANCE(C27,""pe"")"),29.43) -> 29.43 | U27: =IFERROR(__xludf.DUMMYFUNCTION("GOOGLEFINANCE(C27,""marketcap"")"),2.100508458E11) -> 210050845800 | V27: =IFERROR(__xludf.DUMMYFUNCTION("GOOGLEFINANCE(C27,""eps"")"),26.27) -> 26.27 | W27: =IFERROR(__xludf.DUMMYFUNCTION("GOOGLEFINANCE(C27,""high52"")"),1434.5) -> 1434.5 | X27: =H27/W27 -> 0.90394563 | Y27: =IFERROR(__xludf.DUMMYFUNCTION("GOOGLEFINANCE(C27,""low52"")"),772.1) -> 772.1 | Z27: =H27/Y27 -> 1.6794586 | AA27: =IFERROR(__xludf.DUMMYFUNCTION("GOOGLEFINANCE(C27,""volumeavg"")"),1252629.0) -> 1252629 | AB27: =IFERROR(__xludf.DUMMYFUNCTION("GOOGLEFINANCE(C27,""volume"")"),1265431.0) -> 1265431 | AC27: Technology | AD27: Moving
A28: L&T INFOTECH LTD. | B28: 540005 | C28: LTIM | D28: INE214T01019 | E28: Equity | F28: 1 | G28: =IFERROR(__xludf.DUMMYFUNCTION("GOOGLEFINANCE(C28)"),4530.5) -> 4530.5 | H28: 4815 | I28: =H28*F28 -> 4815 | J28: =G28*F28 -> 4530.5 | K28: =J28-I28 -> -284.5 | L28: =K28/I28 -> -0.059086189 | M28: 1 | N28: =(I28 + (M28 * G28)) / (F28 + M28) -> 4672.75 | O28: =G28-N28 -> -142.25 | P28: =O28*F28+M28 -> -141.25 | Q28: =P28/(I28+(G28*M28)) -> -0.015114226 | R28: =IF(Q28 > L28, "Yes", "No") -> Yes | S28: =Q28-L28 -> 0.043971963 | T28: =IFERROR(__xludf.DUMMYFUNCTION("GOOGLEFINANCE(C28,""pe"")"),34.69) -> 34.69 | U28: =IFERROR(__xludf.DUMMYFUNCTION("GOOGLEFINANCE(C28,""marketcap"")"),1.449271E12) -> 1449271000000 | V28: =IFERROR(__xludf.DUMMYFUNCTION("GOOGLEFINANCE(C28,""eps"")"),145.92) -> 145.92 | W28: =IFERROR(__xludf.DUMMYFUNCTION("GOOGLEFINANCE(C28,""high52"")"),6429.5) -> 6429.5 | X28: =H28/W28 -> 0.74889183 | Y28: =IFERROR(__xludf.DUMMYFUNCTION("GOOGLEFINANCE(C28,""low52"")"),3802.0) -> 3802 | Z28: =H28/Y28 -> 1.2664387 | AA28: =IFERROR(__xludf.DUMMYFUNCTION("GOOGLEFINANCE(C28,""volumeavg"")"),365487.0) -> 365487 | AB28: =IFERROR(__xludf.DUMMYFUNCTION("GOOGLEFINANCE(C28,""volume"")"),415582.0) -> 415582 | AC28: Technology | AD28: Moving
A29: LARSEN & TOUBRO LTD. | B29: 500510 | C29: LT | D29: INE018A01030 | E29: Equity | F29: 2 | G29: =IFERROR(__xludf.DUMMYFUNCTION("GOOGLEFINANCE(C29)"),4276.0) -> 4276 | H29: 3373 | I29: =H29*F29 -> 6746 | J29: =G29*F29 -> 8552 | K29: =J29-I29 -> 1806 | L29: =K29/I29 -> 0.2677142 | M29: 1 | N29: =(I29 + (M29 * G29)) / (F29 + M29) -> 3674 | O29: =G29-N29 -> 602 | P29: =O29*F29+M29 -> 1205 | Q29: =P29/(I29+(G29*M29)) -> 0.1093268 | R29: =IF(Q29 > L29, "Yes", "No") -> No | S29: =Q29-L29 -> -0.1583874 | T29: =IFERROR(__xludf.DUMMYFUNCTION("GOOGLEFINANCE(C29,""pe"")"),36.16) -> 36.16 | U29: =IFERROR(__xludf.DUMMYFUNCTION("GOOGLEFINANCE(C29,""marketcap"")"),5.885689358937E12) -> 5885689358937 | V29: =IFERROR(__xludf.DUMMYFUNCTION("GOOGLEFINANCE(C29,""eps"")"),118.13) -> 118.13 | W29: =IFERROR(__xludf.DUMMYFUNCTION("GOOGLEFINANCE(C29,""high52"")"),4440.0) -> 4440 | X29: =H29/W29 -> 0.75968468 | Y29: =IFERROR(__xludf.DUMMYFUNCTION("GOOGLEFINANCE(C29,""low52"")"),2965.3) -> 2965.3 | Z29: =H29/Y29 -> 1.1374903 | AA29: =IFERROR(__xludf.DUMMYFUNCTION("GOOGLEFINANCE(C29,""volumeavg"")"),2043190.0) -> 2043190 | AB29: =IFERROR(__xludf.DUMMYFUNCTION("GOOGLEFINANCE(C29,""volume"")"),1994533.0) -> 1994533 | AC29: Defence | AD29: Moving
A30: LE TRAVENUES TECHNOLOGY L | B30: 544192 | C30: IXIGO | D30: INE0HV901016 | E30: Equity | F30: 13 | G30: =IFERROR(__xludf.DUMMYFUNCTION("GOOGLEFINANCE(C30)"),165.41) -> 165.41 | H30: 149.31 | I30: =H30*F30 -> 1941.03 | J30: =G30*F30 -> 2150.33 | K30: =J30-I30 -> 209.3 | L30: =K30/I30 -> 0.10782935 | M30: 1 | N30: =(I30 + (M30 * G30)) / (F30 + M30) -> 150.46 | O30: =G30-N30 -> 14.95 | P30: =O30*F30+M30 -> 195.35 | Q30: =P30/(I30+(G30*M30)) -> 0.092739409 | R30: =IF(Q30 > L30, "Yes", "No") -> No | S30: =Q30-L30 -> -0.01508994 | T30: =IFERROR(__xludf.DUMMYFUNCTION("GOOGLEFINANCE(C30,""pe"")"),117.61) -> 117.61 | U30: =IFERROR(__xludf.DUMMYFUNCTION("GOOGLEFINANCE(C30,""marketcap"")"),7.2654127778E10) -> 72654127778 | V30: =IFERROR(__xludf.DUMMYFUNCTION("GOOGLEFINANCE(C30,""eps"")"),1.41) -> 1.41 | W30: =IFERROR(__xludf.DUMMYFUNCTION("GOOGLEFINANCE(C30,""high52"")"),339.15) -> 339.15 | X30: =H30/W30 -> 0.44024768 | Y30: =IFERROR(__xludf.DUMMYFUNCTION("GOOGLEFINANCE(C30,""low52"")"),117.0) -> 117 | Z30: =H30/Y30 -> 1.2761538 | AA30: =IFERROR(__xludf.DUMMYFUNCTION("GOOGLEFINANCE(C30,""volumeavg"")"),3045595.0) -> 3045595 | AB30: =IFERROR(__xludf.DUMMYFUNCTION("GOOGLEFINANCE(C30,""volume"")"),2364174.0) -> 2364174 | AC30: Technology | AD30: Moving
A31: MAHINDRA & MAHINDRA LTD. | B31: 500520 | C31: M&M | D31: INE101A01026 | E31: Equity | F31: 2 | G31: =IFERROR(__xludf.DUMMYFUNCTION("GOOGLEFINANCE(C31)"),3421.0) -> 3421 | H31: 1151.9 | I31: =H31*F31 -> 2303.8 | J31: =G31*F31 -> 6842 | K31: =J31-I31 -> 4538.2 | L31: =K31/I31 -> 1.9698759 | M31: 1 | N31: =(I31 + (M31 * G31)) / (F31 + M31) -> 1908.2667 | O31: =G31-N31 -> 1512.7333 | P31: =O31*F31+M31 -> 3026.4667 | Q31: =P31/(I31+(G31*M31)) -> 0.52865893 | R31: =IF(Q31 > L31, "Yes", "No") -> No | S31: =Q31-L31 -> -1.4412169 | T31: =IFERROR(__xludf.DUMMYFUNCTION("GOOGLEFINANCE(C31,""pe"")"),24.43) -> 24.43 | U31: =IFERROR(__xludf.DUMMYFUNCTION("GOOGLEFINANCE(C31,""marketcap"")"),4.108135348433E12) -> 4108135348433 | V31: =IFERROR(__xludf.DUMMYFUNCTION("GOOGLEFINANCE(C31,""eps"")"),140.08) -> 140.08 | W31: =IFERROR(__xludf.DUMMYFUNCTION("GOOGLEFINANCE(C31,""high52"")"),3839.9) -> 3839.9 | X31: =H31/W31 -> 0.29998177 | Y31: =IFERROR(__xludf.DUMMYFUNCTION("GOOGLEFINANCE(C31,""low52"")"),2425.0) -> 2425 | Z31: =H31/Y31 -> 0.47501031 | AA31: =IFERROR(__xludf.DUMMYFUNCTION("GOOGLEFINANCE(C31,""volumeavg"")"),2464736.0) -> 2464736 | AB31: =IFERROR(__xludf.DUMMYFUNCTION("GOOGLEFINANCE(C31,""volume"")"),641895.0) -> 641895 | AC31: EV | AD31: Moving
A32: MOTILALAMC - MOMOMENTUM | B32: 543465 | C32: MOMOMENTUM | D32: INF247L01BK2 | E32: ETF | F32: 6 | G32: =IFERROR(__xludf.DUMMYFUNCTION("GOOGLEFINANCE(C32)"),63.49) -> 63.49 | H32: 71.67 | I32: =H32*F32 -> 430.02 | J32: =G32*F32 -> 380.94 | K32: =J32-I32 -> -49.08 | L32: =K32/I32 -> -0.11413423 | M32: 1 | N32: =(I32 + (M32 * G32)) / (F32 + M32) -> 70.501429 | O32: =G32-N32 -> -7.0114286 | P32: =O32*F32+M32 -> -41.068571 | Q32: =P32/(I32+(G32*M32)) -> -0.083217303 | R32: =IF(Q32 > L32, "Yes", "No") -> Yes | S32: =Q32-L32 -> 0.030916923 | T32: =IFERROR(__xludf.DUMMYFUNCTION("GOOGLEFINANCE(C32,""pe"")"),"#N/A") -> #N/A | U32: =IFERROR(__xludf.DUMMYFUNCTION("GOOGLEFINANCE(C32,""marketcap"")"),"#N/A") -> #N/A | V32: =IFERROR(__xludf.DUMMYFUNCTION("GOOGLEFINANCE(C32,""eps"")"),"#N/A") -> #N/A | W32: =IFERROR(__xludf.DUMMYFUNCTION("GOOGLEFINANCE(C32,""high52"")"),66.37) -> 66.37 | X32: =H32/W32 -> 1.0798554 | Y32: =IFERROR(__xludf.DUMMYFUNCTION("GOOGLEFINANCE(C32,""low52"")"),51.21) -> 51.21 | Z32: =H32/Y32 -> 1.3995313 | AA32: =IFERROR(__xludf.DUMMYFUNCTION("GOOGLEFINANCE(C32,""volumeavg"")"),73541.0) -> 73541 | AB32: =IFERROR(__xludf.DUMMYFUNCTION("GOOGLEFINANCE(C32,""volume"")"),17729.0) -> 17729 | AC32: Others | AD32: Moving
A33: NHPC | B33: 533098 | C33: NHPC | D33: INE848E01016 | E33: Equity | F33: 58 | G33: =IFERROR(__xludf.DUMMYFUNCTION("GOOGLEFINANCE(C33)"),74.72) -> 74.72 | H33: 90.88 | I33: =H33*F33 -> 5271.04 | J33: =G33*F33 -> 4333.76 | K33: =J33-I33 -> -937.28 | L33: =K33/I33 -> -0.1778169 | M33: 1 | N33: =(I33 + (M33 * G33)) / (F33 + M33) -> 90.606102 | O33: =G33-N33 -> -15.886102 | P33: =O33*F33+M33 -> -920.3939 | Q33: =P33/(I33+(G33*M33)) -> -0.17217269 | R33: =IF(Q33 > L33, "Yes", "No") -> Yes | S33: =Q33-L33 -> 0.0056442079 | T33: =IFERROR(__xludf.DUMMYFUNCTION("GOOGLEFINANCE(C33,""pe"")"),23.76) -> 23.76 | U33: =IFERROR(__xludf.DUMMYFUNCTION("GOOGLEFINANCE(C33,""marketcap"")"),7.51368274654E11) -> 751368274654 | V33: =IFERROR(__xludf.DUMMYFUNCTION("GOOGLEFINANCE(C33,""eps"")"),3.15) -> 3.15 | W33: =IFERROR(__xludf.DUMMYFUNCTION("GOOGLEFINANCE(C33,""high52"")"),92.34) -> 92.34 | X33: =H33/W33 -> 0.98418887 | Y33: =IFERROR(__xludf.DUMMYFUNCTION("GOOGLEFINANCE(C33,""low52"")"),71.0) -> 71 | Z33: =H33/Y33 -> 1.28 | AA33: =IFERROR(__xludf.DUMMYFUNCTION("GOOGLEFINANCE(C33,""volumeavg"")"),1.5043452E7) -> 15043452 | AB33: =IFERROR(__xludf.DUMMYFUNCTION("GOOGLEFINANCE(C33,""volume"")"),4933720.0) -> 4933720 | AC33: Green Energy | AD33: Moving
A34: NTPC GREEN ENERGY LIMITED | B34: 544289 | C34: NTPCGREEN | D34: INE0ONG01011 | E34: Equity | F34: 51 | G34: =IFERROR(__xludf.DUMMYFUNCTION("GOOGLEFINANCE(C34)"),89.71) -> 89.71 | H34: 112.72 | I34: =H34*F34 -> 5748.72 | J34: =G34*F34 -> 4575.21 | K34: =J34-I34 -> -1173.51 | L34: =K34/I34 -> -0.20413414 | M34: 1 | N34: =(I34 + (M34 * G34)) / (F34 + M34) -> 112.2775 | O34: =G34-N34 -> -22.5675 | P34: =O34*F34+M34 -> -1149.9425 | Q34: =P34/(I34+(G34*M34)) -> -0.19696091 | R34: =IF(Q34 > L34, "Yes", "No") -> Yes | S34: =Q34-L34 -> 0.0071732252 | T34: =IFERROR(__xludf.DUMMYFUNCTION("GOOGLEFINANCE(C34,""pe"")"),137.39) -> 137.39 | U34: =IFERROR(__xludf.DUMMYFUNCTION("GOOGLEFINANCE(C34,""marketcap"")"),7.55925966875E11) -> 755925966875 | V34: =IFERROR(__xludf.DUMMYFUNCTION("GOOGLEFINANCE(C34,""eps"")"),0.65) -> 0.65 | W34: =IFERROR(__xludf.DUMMYFUNCTION("GOOGLEFINANCE(C34,""high52"")"),117.64) -> 117.64 | X34: =H34/W34 -> 0.95817749 | Y34: =IFERROR(__xludf.DUMMYFUNCTION("GOOGLEFINANCE(C34,""low52"")"),84.05) -> 84.05 | Z34: =H34/Y34 -> 1.3411065 | AA34: =IFERROR(__xludf.DUMMYFUNCTION("GOOGLEFINANCE(C34,""volumeavg"")"),3423668.0) -> 3423668 | AB34: =IFERROR(__xludf.DUMMYFUNCTION("GOOGLEFINANCE(C34,""volume"")"),1874950.0) -> 1874950 | AC34: Green Energy | AD34: Moving
A35: OLECTRA GREENTECH LTD | B35: 532439 | C35: OLECTRA | D35: INE260D01016 | E35: Equity | F35: 7 | G35: =IFERROR(__xludf.DUMMYFUNCTION("GOOGLEFINANCE(C35)"),1016.1) -> 1016.1 | H35: 1493.29 | I35: =H35*F35 -> 10453.03 | J35: =G35*F35 -> 7112.7 | K35: =J35-I35 -> -3340.33 | L35: =K35/I35 -> -0.31955615 | M35: 1 | N35: =(I35 + (M35 * G35)) / (F35 + M35) -> 1433.6412 | O35: =G35-N35 -> -417.54125 | P35: =O35*F35+M35 -> -2921.7888 | Q35: =P35/(I35+(G35*M35)) -> -0.25475243 | R35: =IF(Q35 > L35, "Yes", "No") -> Yes | S35: =Q35-L35 -> 0.064803717 | T35: =IFERROR(__xludf.DUMMYFUNCTION("GOOGLEFINANCE(C35,""pe"")"),58.33) -> 58.33 | U35: =IFERROR(__xludf.DUMMYFUNCTION("GOOGLEFINANCE(C35,""marketcap"")"),8.347610241E10) -> 83476102410 | V35: =IFERROR(__xludf.DUMMYFUNCTION("GOOGLEFINANCE(C35,""eps"")"),17.42) -> 17.42 | W35: =IFERROR(__xludf.DUMMYFUNCTION("GOOGLEFINANCE(C35,""high52"")"),1714.2) -> 1714.2 | X35: =H35/W35 -> 0.87112939 | Y35: =IFERROR(__xludf.DUMMYFUNCTION("GOOGLEFINANCE(C35,""low52"")"),965.1) -> 965.1 | Z35: =H35/Y35 -> 1.5472904 | AA35: =IFERROR(__xludf.DUMMYFUNCTION("GOOGLEFINANCE(C35,""volumeavg"")"),395158.0) -> 395158 | AB35: =IFERROR(__xludf.DUMMYFUNCTION("GOOGLEFINANCE(C35,""volume"")"),268232.0) -> 268232 | AC35: EV | AD35: Moving
A36: PREMIER ENERGIES LIMITED | B36: 544238 | C36: PREMIERENE | D36: INE0BS701011 | E36: Equity | F36: 1 | G36: =IFERROR(__xludf.DUMMYFUNCTION("GOOGLEFINANCE(C36)"),764.45) -> 764.45 | H36: 835 | I36: =H36*F36 -> 835 | J36: =G36*F36 -> 764.45 | K36: =J36-I36 -> -70.55 | L36: =K36/I36 -> -0.084491018 | M36: 1 | N36: =(I36 + (M36 * G36)) / (F36 + M36) -> 799.725 | O36: =G36-N36 -> -35.275 | P36: =O36*F36+M36 -> -34.275 | Q36: =P36/(I36+(G36*M36)) -> -0.021429241 | R36: =IF(Q36 > L36, "Yes", "No") -> Yes | S36: =Q36-L36 -> 0.063061777 | T36: =IFERROR(__xludf.DUMMYFUNCTION("GOOGLEFINANCE(C36,""pe"")"),27.1) -> 27.1 | U36: =IFERROR(__xludf.DUMMYFUNCTION("GOOGLEFINANCE(C36,""marketcap"")"),3.43452568354E11) -> 343452568354 | V36: =IFERROR(__xludf.DUMMYFUNCTION("GOOGLEFINANCE(C36,""eps"")"),28.21) -> 28.21 | W36: =IFERROR(__xludf.DUMMYFUNCTION("GOOGLEFINANCE(C36,""high52"")"),1163.9) -> 1163.9 | X36: =H36/W36 -> 0.71741559 | Y36: =IFERROR(__xludf.DUMMYFUNCTION("GOOGLEFINANCE(C36,""low52"")"),660.0) -> 660 | Z36: =H36/Y36 -> 1.2651515 | AA36: =IFERROR(__xludf.DUMMYFUNCTION("GOOGLEFINANCE(C36,""volumeavg"")"),1936503.0) -> 1936503 | AB36: =IFERROR(__xludf.DUMMYFUNCTION("GOOGLEFINANCE(C36,""volume"")"),430393.0) -> 430393 | AC36: Green Energy | AD36: Moving
A37: RailTel Corporation of India L | B37: 543265 | C37: RAILTEL | D37: INE0DD101019 | E37: Equity | F37: 21 | G37: =IFERROR(__xludf.DUMMYFUNCTION("GOOGLEFINANCE(C37)"),323.0) -> 323 | H37: 450.55 | I37: =H37*F37 -> 9461.55 | J37: =G37*F37 -> 6783 | K37: =J37-I37 -> -2678.55 | L37: =K37/I37 -> -0.28309844 | M37: 1 | N37: =(I37 + (M37 * G37)) / (F37 + M37) -> 444.75227 | O37: =G37-N37 -> -121.75227 | P37: =O37*F37+M37 -> -2555.7977 | Q37: =P37/(I37+(G37*M37)) -> -0.26120749 | R37: =IF(Q37 > L37, "Yes", "No") -> Yes | S37: =Q37-L37 -> 0.021890947 | T37: =IFERROR(__xludf.DUMMYFUNCTION("GOOGLEFINANCE(C37,""pe"")"),32.61) -> 32.61 | U37: =IFERROR(__xludf.DUMMYFUNCTION("GOOGLEFINANCE(C37,""marketcap"")"),1.03598911602E11) -> 103598911602 | V37: =IFERROR(__xludf.DUMMYFUNCTION("GOOGLEFINANCE(C37,""eps"")"),9.9) -> 9.9 | W37: =IFERROR(__xludf.DUMMYFUNCTION("GOOGLEFINANCE(C37,""high52"")"),478.95) -> 478.95 | X37: =H37/W37 -> 0.94070362 | Y37: =IFERROR(__xludf.DUMMYFUNCTION("GOOGLEFINANCE(C37,""low52"")"),265.5) -> 265.5 | Z37: =H37/Y37 -> 1.6969868 | AA37: =IFERROR(__xludf.DUMMYFUNCTION("GOOGLEFINANCE(C37,""volumeavg"")"),1417446.0) -> 1417446 | AB37: =IFERROR(__xludf.DUMMYFUNCTION("GOOGLEFINANCE(C37,""volume"")"),511216.0) -> 511216 | AC37: PSU | AD37: Moving
A38: RVNL | B38: 542649 | C38: RVNL | D38: INE415G01027 | E38: Equity | F38: 14 | G38: =IFERROR(__xludf.DUMMYFUNCTION("GOOGLEFINANCE(C37)"),323.0) -> 323 | H38: 467.18 | I38: =H38*F38 -> 6540.52 | J38: =G38*F38 -> 4522 | K38: =J38-I38 -> -2018.52 | L38: =K38/I38 -> -0.30861766 | M38: 1 | N38: =(I38 + (M38 * G38)) / (F38 + M38) -> 457.568 | O38: =G38-N38 -> -134.568 | P38: =O38*F38+M38 -> -1882.952 | Q38: =P38/(I38+(G38*M38)) -> -0.27434203 | R38: =IF(Q38 > L38, "Yes", "No") -> Yes | S38: =Q38-L38 -> 0.034275635 | T38: =IFERROR(__xludf.DUMMYFUNCTION("GOOGLEFINANCE(C38,""pe"")"),"#N/A") -> #N/A | U38: =IFERROR(__xludf.DUMMYFUNCTION("GOOGLEFINANCE(C38,""marketcap"")"),"#N/A") -> #N/A | V38: =IFERROR(__xludf.DUMMYFUNCTION("GOOGLEFINANCE(C38,""eps"")"),"#N/A") -> #N/A | W38: =IFERROR(__xludf.DUMMYFUNCTION("GOOGLEFINANCE(C38,""high52"")"),75.05) -> 75.05 | X38: =H38/W38 -> 6.2249167 | Y38: =IFERROR(__xludf.DUMMYFUNCTION("GOOGLEFINANCE(C38,""low52"")"),24.49) -> 24.49 | Z38: =H38/Y38 -> 19.076358 | AA38: =IFERROR(__xludf.DUMMYFUNCTION("GOOGLEFINANCE(C38,""volumeavg"")"),46893.0) -> 46893 | AB38: =IFERROR(__xludf.DUMMYFUNCTION("GOOGLEFINANCE(C38,""volume"")"),0.0) -> 0 | AC38: PSU | AD38: Moving
A39: SITI CABLE NET-EQ | B39: 532795 | C39: SITINET | D39: INE965H01011 | E39: Equity | F39: 100 | G39: =IFERROR(__xludf.DUMMYFUNCTION("GOOGLEFINANCE(C39)"),0.37) -> 0.37 | H39: 0.83 | I39: =H39*F39 -> 83 | J39: =G39*F39 -> 37 | K39: =J39-I39 -> -46 | L39: =K39/I39 -> -0.55421687 | M39: 1 | N39: =(I39 + (M39 * G39)) / (F39 + M39) -> 0.82544554 | O39: =G39-N39 -> -0.45544554 | P39: =O39*F39+M39 -> -44.544554 | Q39: =P39/(I39+(G39*M39)) -> -0.53429956 | R39: =IF(Q39 > L39, "Yes", "No") -> Yes | S39: =Q39-L39 -> 0.019917306 | T39: =IFERROR(__xludf.DUMMYFUNCTION("GOOGLEFINANCE(C39,""pe"")"),"#N/A") -> #N/A | U39: =IFERROR(__xludf.DUMMYFUNCTION("GOOGLEFINANCE(C39,""marketcap"")"),3.4010097E8) -> 340100970 | V39: =IFERROR(__xludf.DUMMYFUNCTION("GOOGLEFINANCE(C39,""eps"")"),-2.48) -> -2.48 | W39: =IFERROR(__xludf.DUMMYFUNCTION("GOOGLEFINANCE(C39,""high52"")"),0.64) -> 0.64 | X39: =H39/W39 -> 1.296875 | Y39: =IFERROR(__xludf.DUMMYFUNCTION("GOOGLEFINANCE(C39,""low52"")"),0.31) -> 0.31 | Z39: =H39/Y39 -> 2.6774194 | AA39: =IFERROR(__xludf.DUMMYFUNCTION("GOOGLEFINANCE(C39,""volumeavg"")"),555827.0) -> 555827 | AB39: =IFERROR(__xludf.DUMMYFUNCTION("GOOGLEFINANCE(C39,""volume"")"),64395.0) -> 64395 | AC39: Others | AD39: Non Moving
A40: SJVN | B40: 533206 | C40: SJVN | D40: INE002L01015 | E40: Equity | F40: 97 | G40: =IFERROR(__xludf.DUMMYFUNCTION("GOOGLEFINANCE(C40)"),73.62) -> 73.62 | H40: 129.74 | I40: =H40*F40 -> 12584.78 | J40: =G40*F40 -> 7141.14 | K40: =J40-I40 -> -5443.64 | L40: =K40/I40 -> -0.43255742 | M40: 1 | N40: =(I40 + (M40 * G40)) / (F40 + M40) -> 129.16735 | O40: =G40-N40 -> -55.547347 | P40: =O40*F40+M40 -> -5387.0927 | Q40: =P40/(I40+(G40*M40)) -> -0.42557453 | R40: =IF(Q40 > L40, "Yes", "No") -> Yes | S40: =Q40-L40 -> 0.0069828908 | T40: =IFERROR(__xludf.DUMMYFUNCTION("GOOGLEFINANCE(C40,""pe"")"),45.36) -> 45.36 | U40: =IFERROR(__xludf.DUMMYFUNCTION("GOOGLEFINANCE(C40,""marketcap"")"),2.89429407746E11) -> 289429407746 | V40: =IFERROR(__xludf.DUMMYFUNCTION("GOOGLEFINANCE(C40,""eps"")"),1.62) -> 1.62 | W40: =IFERROR(__xludf.DUMMYFUNCTION("GOOGLEFINANCE(C40,""high52"")"),107.5) -> 107.5 | X40: =H40/W40 -> 1.2068837 | Y40: =IFERROR(__xludf.DUMMYFUNCTION("GOOGLEFINANCE(C40,""low52"")"),68.13) -> 68.13 | Z40: =H40/Y40 -> 1.9043006 | AA40: =IFERROR(__xludf.DUMMYFUNCTION("GOOGLEFINANCE(C40,""volumeavg"")"),6934991.0) -> 6934991 | AB40: =IFERROR(__xludf.DUMMYFUNCTION("GOOGLEFINANCE(C40,""volume"")"),2418898.0) -> 2418898 | AC40: Green Energy | AD40: Moving
...

Sheet Technical_Indicators
A1: Symbol | B1: StartDate | C1: EndDate | D1: Beta | E1: RSI | F1: SMA_50 | G1: EMA_12 | H1: MACD | I1: Bollinger_Upper | J1: Bollinger_Middle | K1: Bollinger_Lower | L1: ATR_14 | M1: Processed
A2: =Portfolio!C2 -> ADANIGREEN | B2: =TODAY()-1095 -> 44982 | C2: =Today() -> 46077 | D2: 1.3713 | E2: 27.18 | F2: 996.81 | G2: 879.29 | H2: -47.83 | I2: 1047.62 | J2: 936.04 | K2: 824.46 | L2: 17.37 | M2: 45713
A3: =Portfolio!C3 -> ADANIPOWER | B3: =TODAY()-1095 -> 44982 | C3: =Today() -> 46077 | D3: 1.2977 | E3: 35.3 | F3: 508.63 | G3: 484.62 | H3: -9.99 | I3: 520.75 | J3: 496.11 | K3: 471.47 | L3: 4.55 | M3: 45713
A4: =Portfolio!C4 -> AEROFLEX | B4: =TODAY()-1095 -> 44982 | C4: =Today() -> 46077 | D4: 1.1401 | E4: 39.3 | F4: 216.13 | G4: 200.72 | H4: -16.71 | I4: 271.01 | J4: 222.4 | K4: 173.79 | L4: 10.35 | M4: 45713
A5: =Portfolio!C5 -> ASHOKLEY | B5: =TODAY()-1095 -> 44982 | C5: =Today() -> 46077 | D5: 1.2102 | E5: 56.32 | F5: 215.93 | G5: 220.77 | H5: 5.12 | I5: 229.28 | J5: 214.64 | K5: 200.01 | L5: 3.82 | M5: 45713
A6: =Portfolio!C6 -> ASTRAMICRO | B6: =TODAY()-1095 -> 44982 | C6: =Today() -> 46077 | D6: 1.2169 | E6: 33.62 | F6: 733.37 | G6: 628.94 | H6: -35.27 | I6: 758.82 | J6: 670.7 | K6: 582.57 | L6: 15.64 | M6: 45713
A7: =Portfolio!C7 -> AXISCADES | B7: =TODAY()-1095 -> 44982 | C7: =Today() -> 46077 | D7: 1.1929 | E7: 48.74 | F7: 710.44 | G7: 725.99 | H7: 2 | I7: 788.76 | J7: 732.31 | K7: 675.85 | L7: 22.66 | M7: 45719
A8: =Portfolio!C8 -> NSE:BDL | B8: =TODAY()-1095 -> 44982 | C8: =Today() -> 46077 | D8: 1.0486 | E8: 32.78 | F8: 1164.44 | G8: 1027.64 | H8: -68.68 | I8: 1294.88 | J8: 1112.3 | K8: 929.71 | L8: 27.88 | M8: 45719
A9: =Portfolio!C9 -> NSE:BEL | B9: =TODAY()-1095 -> 44982 | C9: =Today() -> 46077 | D9: 1.2982 | E9: 37.83 | F9: 274.22 | G9: 253.06 | H9: -7.64 | I9: 292.54 | J9: 264.06 | K9: 235.57 | L9: 4.86 | M9: 45719
A10: =Portfolio!C10 -> BHARTIHEXA | B10: =TODAY()-1095 -> 44982 | C10: =Today() -> 46077 | D10: 1.1243 | E10: 45.04 | F10: 1385.37 | G10: 1312.81 | H10: -19.81 | I10: 1434.96 | J10: 1344.17 | K10: 1253.37 | L10: 27.54 | M10: 45719
A11: =Portfolio!C11 -> CGPOWER | B11: =TODAY()-1095 -> 44982 | C11: =Today() -> 46077 | D11: 0.8744 | E11: 41.17 | F11: 644.38 | G11: 584.67 | H11: -7.09 | I11: 631.87 | J11: 593.01 | K11: 554.15 | L11: 12.2 | M11: 45719
A12: =Portfolio!C12 -> COCHINSHIP | B12: =TODAY()-1095 -> 44982 | C12: =Today() -> 46077 | D12: 1.1641 | E12: 38.68 | F12: 1423.45 | G12: 1285.49 | H12: -40.19 | I12: 1481.87 | J12: 1331.46 | K12: 1181.06 | L12: 23.68 | M12: 45719
A13: =Portfolio!C13 -> CPSEETF | B13: =TODAY()-1095 -> 44982 | C13: =Today() -> 46077 | D13: 0.9369 | E13: 37.03 | F13: 82.87 | G13: 78.27 | H13: -1.43 | I13: 85.39 | J13: 80.08 | K13: 74.76 | L13: 1.11 | M13: 45719
... A18: =Portfolio!C18 -> HATHWAY | B18: =TODAY()-1095 -> 44982 | C18: =Today() -> 46077 | D18: 0.9858 | E18: 31.3 | F18: 15.06 | G18: 13.83 | H18: -0.38 | I18: 15.31 | J18: 14.28 | K18: 13.25 | L18: 0.26 | M18: 45719
A19: =Portfolio!C19 -> HBLENGINE | B19: =TODAY()-1095 -> 44982 | C19: =Today() -> 46077 | D19: 2.6384 | E19: 31.37 | F19: N/A | G19: 466.93 | H19: -29.91 | I19: 606.3 | J19: 509.02 | K19: 411.74 | L19: 17.88 | M19: 45719
A20: =Portfolio!C20 -> ICICIB22 | B20: =TODAY()-1095 -> 44982 | C20: =Today() -> 46077 | D20: 0.9775 | E20: 30.98 | F20: 102.87 | G20: 96.8 | H20: -1.66 | I20: 104.37 | J20: 98.9 | K20: 93.42 | L20: 0.87 | M20: 45719
A21: =Portfolio!C21 -> GOLDIETF | B21: =TODAY()-1095 -> 44982 | C21: =Today() -> 46077 | D21: 0.0722 | E21: 56.22 | F21: 70.19 | G21: 74.31 | H21: 0.66 | I21: 75.8 | J21: 73.85 | K21: 71.91 | L21: 0.49 | M21: 45719
A22: =Portfolio!C22 -> IDFCFIRSTB | B22: =TODAY()-1095 -> 44982 | C22: =Today() -> 46077 | D22: 1.1996 | E22: 39.41 | F22: 61.87 | G22: 59.8 | H22: -0.9 | I22: 64.61 | J22: 61.34 | K22: 58.08 | L22: 0.93 | M22: 45719
A23: =Portfolio!C23 -> IRCTC | B23: =TODAY()-1095 -> 44982 | C23: =Today() -> 46077 | D23: 1.2224 | E23: 28.31 | F23: 764.41 | G23: 712.29 | H23: -24.8 | I23: 817.39 | J23: 746.25 | K23: 675.11 | L23: 10.87 | M23: 45719
A24: =Portfolio!C24 -> IRFC | B24: =TODAY()-1095 -> 44982 | C24: =Today() -> 46077 | D24: 1.1458 | E24: 27.35 | F24: 137.72 | G24: 121.19 | H24: -5.77 | I24: 144.98 | J24: 127.95 | K24: 110.92 | L24: 2.51 | M24: 45719
A25: =Portfolio!C25 -> IRCON | B25: =TODAY()-1095 -> 44982 | C25: =Today() -> 46077 | D25: 1.3802 | E25: 27.37 | F25: 192.76 | G25: 153.54 | H25: -14.62 | I25: 212.49 | J25: 171.58 | K25: 130.67 | L25: 4.83 | M25: 45719
A26: =Portfolio!C26 -> INDOWIND | B26: =TODAY()-1095 -> 44982 | C26: =Today() -> 46077 | D26: 0.9568 | E26: 27.51 | F26: 22.24 | G26: 17.42 | H26: -1.89 | I26: 25.44 | J26: 19.98 | K26: 14.51 | L26: 0.71 | M26: 45719
A27: =Portfolio!C27 -> KPITTECH | B27: =TODAY()-1095 -> 44982 | C27: =Today() -> 46077 | D27: 0.9423 | E27: 28.09 | F27: 1377.62 | G27: 1285.84 | H27: -44.28 | I27: 1486.92 | J27: 1352.78 | K27: 1218.63 | L27: 23.28 | M27: 45719
A28: =Portfolio!C28 -> LTIM | B28: =TODAY()-1095 -> 44982 | C28: =Today() -> 46077 | D28: 0.89 | E28: 23.12 | F28: 5706.81 | G28: 5144.4 | H28: -293.58 | I28: 6296.64 | J28: 5534.38 | K28: 4772.12 | L28: 124.16 | M28: 45719
A29: =Portfolio!C29 -> LT | B29: =TODAY()-1095 -> 44982 | C29: =Today() -> 46077 | D29: 1.1838 | E29: 34.75 | F29: 3455.06 | G29: 3234.69 | H29: -53.97 | I29: 3473.09 | J29: 3294.68 | K29: 3116.27 | L29: 33.08 | M29: 45719
A30: =Portfolio!C30 -> IXIGO | B30: =TODAY()-1095 -> 44982 | C30: =Today() -> 46077 | D30: 1.092 | E30: 36.43 | F30: 151.81 | G30: 140.73 | H30: -2.95 | I30: 160.93 | J30: 146.51 | K30: 132.09 | L30: 3 | M30: 45719
A31: =Portfolio!C31 -> M&M | B31: =TODAY()-1095 -> 44982 | C31: =Today() -> 46077 | D31: 1.1493 | E31: 32.75 | F31: 2964.28 | G31: 2747.17 | H31: -121.69 | I31: 3321.12 | J31: 2934.36 | K31: 2547.6 | L31: 71.03 | M31: 45719
... A42: =Portfolio!C42 -> TMPV | B42: =TODAY()-1095 -> 44982 | C42: =Today() -> 46077 | D42: 1.2228 | E42: 26.68 | F42: 725.84 | G42: 663.03 | H42: -18.47 | I42: 729.71 | J42: 684.11 | K42: 638.51 | L42: 9.2 | M42: 45719
A43: NSE:TMCV | B43: 45970 | C43: =Today() -> 46077
A44: =Portfolio!C44 -> TATAPOWER | B44: =TODAY()-1095 -> 44982 | C44: =Today() -> 46077 | D44: 1.3305 | E44: 37.96 | F44: 366.36 | G44: 347 | H44: -3.74 | I44: 371.78 | J44: 352.44 | K44: 333.09 | L44: 4.96 | M44: 45719
A45: =Portfolio!C45 -> TATASTEEL | B45: =TODAY()-1095 -> 44982 | C45: =Today() -> 46077 | D45: 1.3028 | E45: 53.7 | F45: 133.94 | G45: 137.19 | H45: 1.88 | I45: 140.52 | J45: 135.31 | K45: 130.1 | L45: 2.11 | M45: 45719
A46: =Portfolio!C46 -> TATATECH | B46: =TODAY()-1095 -> 44982 | C46: =Today() -> 46077 | D46: 0.6358 | E46: 23.14 | F46: 804.92 | G46: 720.81 | H46: -19.74 | I46: 804.06 | J46: 746.1 | K46: 688.14 | L46: 11.35 | M46: 45719
A47: =Portfolio!C47 -> NSE:TCS | B47: =TODAY()-1095 -> 44982 | C47: =Today() -> 46077 | D47: 0.8347 | E47: 16.22 | F47: 4041.69 | G47: 3704.97 | H47: -145.59 | I47: 4251.18 | J47: 3890.76 | K47: 3530.33 | L47: 44.56 | M47: 45719
A48: =Portfolio!C48 -> TEXRAIL | B48: =TODAY()-1095 -> 44982 | C48: =Today() -> 46077 | D48: 1.3536 | E48: 28.76 | F48: 176.05 | G48: 139.71 | H48: -10.32 | I48: 180.46 | J48: 150.97 | K48: 121.48 | L48: 3.96 | M48: 45719
A49: =Portfolio!C49 -> WAAREEENER | B49: =TODAY()-1095 -> 44982 | C49: =Today() -> 46077 | D49: 1.1613 | E49: 40.37 | F49: 2477.05 | G49: 2214.14 | H49: -17.42 | I49: 2410.38 | J49: 2250.73 | K49: 2091.07 | L49: 49.7 | M49: 45719
A50: =Portfolio!C50 -> WIPRO | B50: =TODAY()-1095 -> 44982 | C50: =Today() -> 46077 | D50: 1.0984 | E50: 29.7 | F50: 304.35 | G50: 298.42 | H50: -6.99 | I50: 329.11 | J50: 308.18 | K50: 287.24 | L50: 4.74 | M50: 45719
A51: =Portfolio!C51 -> ETERNAL | B51: =TODAY()-1095 -> 44982 | C51: =Today() -> 46077 | D51: 1.1935 | E51: 45.16 | F51: 239.82 | G51: 225.45 | H51: 0.9 | I51: 240.08 | J51: 225.91 | K51: 211.73 | L51: 4.79 | M51: 45719

Sheet Watchlist
A1: Scrip Name | B1: Scrip Code | C1: Symbol | D1: ISIN | E1: 250 | F1: Price | G1: Change | H1: Change Pct | I1: 5 | J1: 10 | K1: 5 | L1: 10 | M1: Market Cap | N1: PE | O1: Segement
A2: ADANI GREEN ENERGY LTD | B2: 541450 | C2: ADANIGREEN | D2: INE364U01010 | E2: =IFERROR(__xludf.DUMMYFUNCTION("SPARKLINE(INDEX(GOOGLEFINANCE(C2,""price"",workday(today(),-$E$1),today()),,2),{""charttype"",""column"";""color"",""green""})"),"") | F2: =IFERROR(__xludf.DUMMYFUNCTION("GOOGLEFINANCE(C2,""price"")"),961.4) -> 961.4 | G2: =IFERROR(__xludf.DUMMYFUNCTION("GOOGLEFINANCE(C2,""change"")"),-8.95) -> -8.95 | H2: =IFERROR(__xludf.DUMMYFUNCTION("GOOGLEFINANCE(C2,""changepct"")/100"),-0.0092) -> -0.0092 | I2: =IFERROR(__xludf.DUMMYFUNCTION("INDEX(GOOGLEFINANCE(C2,""price"",workday(today(),-I$1)),2,2)"),1016.8) -> 1016.8 | J2: =IFERROR(__xludf.DUMMYFUNCTION("INDEX(GOOGLEFINANCE($C2,""price"",workday(today(),-J$1)),2,2)"),978.3) -> 978.3 | K2: =IFERROR(__xludf.DUMMYFUNCTION("$F2/(INDEX(GOOGLEFINANCE($C2,""price"",workday(today(),-K$1)),2,2))-1"),-0.05448465774980327) -> -0.054484658 | L2: =IFERROR(__xludf.DUMMYFUNCTION("$F2/(INDEX(GOOGLEFINANCE($C2,""price"",workday(today(),-L$1)),2,2))-1"),-0.017274864560973047) -> -0.017274865 | M2: =IFERROR(__xludf.DUMMYFUNCTION("GOOGLEFINANCE(C2,""marketcap"")"),1.583594085214E12) -> 1583594085214 | N2: =IFERROR(__xludf.DUMMYFUNCTION("IFERROR(GOOGLEFINANCE(C2,""PE""),""-"")"),111.62) -> 111.62 | O2: Green Energy
